Workbook

Sheet 00_TongQuan
A1: KẾ HOẠCH TỔNG THỂ NÂNG CẤP CEPH – 10 TUẦN
A3: Production-ready procedure + Lab validation | Không bao gồm thay đổi trực tiếp trên Production
A5: TỔNG ĐẦU VIỆC | F5: ĐÃ HOÀN THÀNH | J5: TIẾN ĐỘ
A6: =COUNTA('01_KeHoach'!A6:A120) -> 82 | F6: =COUNTIF('01_KeHoach'!L6:L120,"Hoàn thành") -> 0 | J6: =IFERROR(F6/B6,0) -> 0
A10: TÀI LIỆU ĐẦU RA | F10: CHECKLIST | J10: TEST CASE LAB
A11: =COUNTA('03_DanhMucTaiLieu'!A6:A100) -> 18 | F11: =COUNTA('04_DanhMucChecklist'!A6:A100) -> 21 | J11: =COUNTA('05_LabTest'!A6:A100) -> 27
A15: PHẠM VI VÀ GIẢ ĐỊNH KẾ HOẠCH
A16: Ngày bắt đầu | B16: 46258 | F16: Ngày kết thúc | G16: 46325 | J16: Thời lượng | K16: 10 tuần / 50 ngày làm việc
A17: Hiện trạng | B17: Ceph Pacific 16.2.5 | F17: Target ứng viên | G17: Target cuối chốt tại G1; revalidate trước Lab/H1 | J17: Đường ứng viên | K17: Pacific 16.2.5 → Pacific 16.2.15 → Quincy 17.2.x → Reef 18.2.7
A18: Phạm vi | B18: Khảo sát, thiết kế, Lab, rehearsal, báo cáo | F18: Ngoài phạm vi | G18: Thực thi thay đổi trên Production | J18: Nguyên tắc | K18: Mỗi hop có 1 tuần riêng, pre-check, monitoring, exit gate và soak
A19: Ngưỡng SLA | B19: Chốt sau As-Is W1 và baseline W6 | F19: Rollback | G19: Ưu tiên pause/fix-forward; backup phục vụ recovery | J19: UNKNOWN critical | K19: UNKNOWN critical được xử lý như BLOCK
A21: LỘ TRÌNH THEO GIAI ĐOẠN
A22: Giai đoạn | C22: Tuần | D22: Mục tiêu | G22: Đầu ra chính | M22: Gate
A23: 1. Khảo sát As-Is | C23: Tuần 1 | D23: Thu thập fact, workload và blocker | G23: As-Is Checklist + As-Is Report + Blocker Register | M23: G0
A24: 2. Target, Hops & Compatibility | C24: Tuần 2–3 | D24: Chốt target, hop và compatibility theo từng hop | G24: Decision Record + Compatibility Matrix H1/H2/H3 + revalidation | M24: G1
A25: 3. Thiết kế Production-ready | C25: Tuần 4 | D25: Hoàn thiện runbook/checklist/backup/rollback/test plan v0.1 | G25: Bộ tài liệu thiết kế + tiêu chí evidence và gate | M25: G2
A26: 4. Dựng Lab & Baseline | C26: Tuần 5–6 | D26: Dựng Lab tương đồng, automation và baseline | G26: Equivalence Matrix + Evidence Collector + IO Sentinel + baseline | M26: G3
A27: 5. Test từng hop | C27: Tuần 7–9 | D27: Mỗi hop một tuần dưới IO liên tục | G27: Evidence/KPI/checklist/soak/exit gate H1–H3 | M27: G4–G9
A28: 6. Resilience, rehearsal & bàn giao | C28: Tuần 10 | D28: Fault/failure/restore/rehearsal và chốt hồ sơ | G28: Traceability + Lab report + Runbook v1.0 + recommendation | M28: G10–G11

Sheet 01_KeHoach
A1: WBS – KẾ HOẠCH CÔNG VIỆC 10 TUẦN
A3: Ngày kế hoạch: 2026-08-24 đến 2026-10-30 | Cập nhật cột Trạng thái trong quá trình thực hiện
A5: WBS | B5: Giai đoạn | C5: Tuần | D5: Công việc | E5: Chi tiết thực hiện | F5: Phụ thuộc | G5: Bắt đầu | H5: Kết thúc | I5: Đầu ra / Evidence | J5: Gate | K5: Ưu tiên | L5: Trạng thái | M5: Ghi chú
A6: WBS-1.1 | B6: Khởi động & As-Is | C6: W1 | D6: Kick-off, chốt phạm vi và mục tiêu | E6: Xác nhận đầu ra: nghiên cứu, quy trình Production-ready, Lab validation; không triển khai Production. | F6: - | G6: 46258 | H6: 46258 | I6: Biên bản phạm vi | K6: Critical | L6: Chưa bắt đầu
A7: WBS-1.2 | B7: Khởi động & As-Is | C7: W1 | D7: Chốt tiêu chí nghiệm thu và SLA cần đo | E7: Xác định availability, error rate, p95/p99 latency, throughput, data integrity; giá trị ngưỡng chốt sau baseline. | F7: 1.1 | G7: 46258 | H7: 46259 | I7: Acceptance criteria v0.1 | K7: Critical | L7: Chưa bắt đầu
A8: WBS-1.3 | B8: Khởi động & As-Is | C8: W1 | D8: Thiết lập evidence repository, index và yêu cầu Evidence Collector | E8: Chuẩn hóa nơi lưu, naming, checksum, timestamp và đặc tả collector cho command/log/KPI. | F8: 1.1 | G8: 46258 | H8: 46259 | I8: Evidence index + collector specification | K8: High | L8: Chưa bắt đầu
A9: WBS-1.4 | B9: Khởi động & As-Is | C9: W1 | D9: Tạo As-Is Survey Checklist v0.1 | E9: Biến các trường cần khảo sát thành mục có cách kiểm tra, evidence và PASS/BLOCK/UNKNOWN. | F9: 1.1 | G9: 46258 | H9: 46259 | I9: As-Is Checklist v0.1 | K9: Critical | L9: Chưa bắt đầu
A10: WBS-1.5 | B10: Khởi động & As-Is | C10: W1 | D10: Khảo sát deployment và topology | E10: cephadm/package/ceph-ansible; host, MON/MGR/OSD/MDS/RGW/gateway, managed scope. | F10: 1.4 | G10: 46259 | H10: 46259 | I10: Topology + deployment evidence | K10: Critical | L10: Chưa bắt đầu
A11: WBS-1.6 | B11: Khởi động & As-Is | C11: W1 | D11: Khảo sát version distribution | E11: Xác minh version thực tế của từng daemon và phát hiện mixed-version tồn tại. | F11: 1.4 | G11: 46259 | H11: 46259 | I11: Daemon/version inventory | K11: Critical | L11: Chưa bắt đầu
A12: WBS-1.7 | B12: Khởi động & As-Is | C12: W1 | D12: Khảo sát BlueStore/RocksDB và DB/WAL | E12: Xác minh objectstore, block/block.db/block.wal, OSD metadata, disk health. | F12: 1.4 | G12: 46259 | H12: 46260 | I12: Storage backend inventory | K12: Critical | L12: Chưa bắt đầu
A13: WBS-1.8 | B13: Khởi động & As-Is | C13: W1 | D13: Khảo sát pool, PG, CRUSH, capacity và health history | E13: Pool replication/EC, size/min_size, autoscaler, failure domain, utilization, nearfull/backfillfull. | F13: 1.4 | G13: 46260 | H13: 46260 | I13: Pool/PG/CRUSH report | K13: Critical | L13: Chưa bắt đầu
A14: WBS-1.9 | B14: Khởi động & As-Is | C14: W1 | D14: Khảo sát dịch vụ và client | E14: RGW/RBD/CephFS/NFS/iSCSI/mirror; IAM, Lifecycle, Versioning, Object Lock; client OS/kernel/library. | F14: 1.4 | G14: 46260 | H14: 46261 | I14: Service/client inventory | K14: Critical | L14: Chưa bắt đầu
A15: WBS-1.10 | B15: Khởi động & As-Is | C15: W1 | D15: Khảo sát host platform và delivery artifact | E15: OS, kernel, container runtime, registry/repo, network, DNS/NTP, SSH/sudo/OOB. | F15: 1.4 | G15: 46261 | H15: 46261 | I15: Host cohort matrix | K15: Critical | L15: Chưa bắt đầu
A16: WBS-1.11 | B16: Khởi động & As-Is | C16: W1 | D16: Khảo sát workload Production | E16: IOPS, throughput, object/block size, read/write mix, concurrency, peak window, SLO và backup hiện tại. | F16: 1.2 | G16: 46261 | H16: 46261 | I16: Workload profile As-Is | K16: Critical | L16: Chưa bắt đầu
A17: WBS-1.12 | B17: Khởi động & As-Is | C17: W1 | D17: Phát hành As-Is Report và Blocker Register | E17: Chỉ dùng fact có evidence; UNKNOWN critical được đưa vào blocker. | F17: 1.5–1.11 | G17: 46262 | H17: 46262 | I17: As-Is Report + blockers | J17: G0 | K17: Critical | L17: Chưa bắt đầu
A18: WBS-2.1 | B18: Target & Compatibility | C18: W2 | D18: Nghiên cứu target ứng viên | E18: So sánh vòng đời hỗ trợ, ổn định, security fix, phương thức triển khai và rủi ro vận hành. | F18: 1.12 | G18: 46265 | H18: 46267 | I18: Target options analysis | K18: Critical | L18: Chưa bắt đầu
A19: WBS-2.2 | B19: Target & Compatibility | C19: W2 | D19: Xác minh đường nâng cấp được hỗ trợ | E19: Đối chiếu official upgrade/release notes; không bỏ qua major hop chưa được xác nhận. | F19: 1.12 | G19: 46265 | H19: 46267 | I19: Supported-path evidence | K19: Critical | L19: Chưa bắt đầu
A20: WBS-2.3 | B20: Target & Compatibility | C20: W2 | D20: Định nghĩa tiêu chí chọn target | E20: Support lifecycle, OS/client/vendor, feature, risk, thời gian Lab, khả năng fix-forward. | F20: 2.1 | G20: 46265 | H20: 46266 | I20: Decision criteria | K20: High | L20: Chưa bắt đầu
A21: WBS-2.4 | B21: Target & Compatibility | C21: W2 | D21: Thiết kế schema compatibility matrix | E21: From/To, deployment, OS/kernel, backend, daemon/service/client, feature/config, known issue, gate, evidence. | F21: 2.2 | G21: 46267 | H21: 46269 | I21: Matrix template | K21: Critical | L21: Chưa bắt đầu
A22: WBS-2.5 | B22: Target & Compatibility | C22: W3 | D22: Lập Compatibility Matrix H1 | E22: Pacific 16.2.5 → 16.2.15; patch, image/repo, daemon, dịch vụ, regression và exit criteria. | F22: 2.4 | G22: 46272 | H22: 46273 | I22: Compatibility H1 | K22: Critical | L22: Chưa bắt đầu
A23: WBS-2.6 | B23: Target & Compatibility | C23: W3 | D23: Lập Compatibility Matrix H2 | E23: Pacific 16.2.15 → Quincy 17.2.x; backend, OS/client, daemon/service, config, blocker. | F23: 2.4 | G23: 46272 | H23: 46274 | I23: Compatibility H2 | K23: Critical | L23: Chưa bắt đầu
A24: WBS-2.7 | B24: Target & Compatibility | C24: W3 | D24: Lập Compatibility Matrix H3 | E24: Quincy 17.2.x → Reef 18.2.7; client/service, BlueStore/RocksDB, config, regression. | F24: 2.4 | G24: 46273 | H24: 46275 | I24: Compatibility H3 | K24: Critical | L24: Chưa bắt đầu
A25: WBS-2.8 | B25: Target & Compatibility | C25: W3 | D25: Đánh giá blocker và biện pháp xử lý | E25: Phân loại BLOCK/CONDITIONAL/PASS; chốt owner và deadline cho từng blocker. | F25: 2.5–2.7 | G25: 46274 | H25: 46275 | I25: Mitigation register | K25: Critical | L25: Chưa bắt đầu
A26: WBS-2.9 | B26: Target & Compatibility | C26: W3 | D26: Lập Target & Hop Decision Record | E26: Ghi rõ target cuối, transit version, lý do chọn và điều kiện xem xét lại. | F26: 2.8 | G26: 46275 | H26: 46276 | I26: Decision Record | K26: Critical | L26: Chưa bắt đầu
A27: WBS-2.10 | B27: Target & Compatibility | C27: W3 | D27: Revalidate release status/support và chốt target/hop | E27: Xác minh lại patch release, vòng đời hỗ trợ và đường nâng cấp trước khi khóa thiết kế Lab. | F27: 2.9 | G27: 46276 | H27: 46276 | I27: Approved Target & Hop Decision Record | J27: G1 | K27: Critical | L27: Chưa bắt đầu
A28: WBS-3.1 | B28: Thiết kế quy trình | C28: W4 | D28: Xây Master Upgrade Strategy | E28: Mục tiêu minimal downtime, nguyên tắc rolling, change window, vai trò, gate và evidence. | F28: 2.5–2.7 | G28: 46279 | H28: 46280 | I28: Upgrade Strategy v0.1 | K28: Critical | L28: Chưa bắt đầu
A29: WBS-3.2 | B29: Thiết kế quy trình | C29: W4 | D29: Tạo Master Runbook skeleton | E29: Bố cục pre-check, backup, thực thi, monitoring, post-check, pause/stop, exit gate từng hop. | F29: 3.1 | G29: 46279 | H29: 46283 | I29: Runbook v0.1 | K29: Critical | L29: Chưa bắt đầu
A30: WBS-3.3 | B30: Thiết kế quy trình | C30: W4 | D30: Hoàn thiện As-Is Checklist | E30: Bổ sung command/evidence/owner/status và liên kết tới compatibility item. | F30: 1.12 | G30: 46279 | H30: 46279 | I30: As-Is Checklist v1.0 | K30: High | L30: Chưa bắt đầu
A31: WBS-3.4 | B31: Thiết kế quy trình | C31: W4 | D31: Tạo Pre-upgrade Readiness Checklist chung | E31: Health, quorum, OSD/PG, capacity, backend, client, artifact, monitoring, access, CAB. | F31: 2.8 | G31: 46279 | H31: 46280 | I31: Readiness Checklist v0.1 | K31: Critical | L31: Chưa bắt đầu
A32: WBS-3.5 | B32: Thiết kế quy trình | C32: W4 | D32: Tạo Pre-hop Checklist H1/H2/H3 | E32: Thêm điều kiện đặc thù version, backup checkpoint và final readiness T-30 phút. | F32: 3.4 | G32: 46280 | H32: 46281 | I32: 3 Pre-hop Checklists | K32: Critical | L32: Chưa bắt đầu
A33: WBS-3.6 | B33: Thiết kế quy trình | C33: W4 | D33: Tạo Rolling Monitoring Checklist chung | E33: Upgrade status, health, quorum, OSD/PG, crash, recovery, client I/O, latency/error rate, CONTINUE/PAUSE/STOP. | F33: 3.2 | G33: 46280 | H33: 46281 | I33: Monitoring common v0.1 | K33: Critical | L33: Chưa bắt đầu
A34: WBS-3.7 | B34: Thiết kế quy trình | C34: W4 | D34: Tạo Monitoring Checklist H1/H2/H3 | E34: Bổ sung mixed-version expectation, daemon batch, known risk và evidence cho từng hop. | F34: 3.6 | G34: 46281 | H34: 46282 | I34: 3 Hop Monitoring Checklists | K34: Critical | L34: Chưa bắt đầu
A35: WBS-3.8 | B35: Thiết kế quy trình | C35: W4 | D35: Tạo Exit Gate & Soak Checklist H1/H2/H3 | E35: Version convergence, functional/data integrity, health ổn định, soak duration và GO sang hop tiếp theo. | F35: 3.5–3.7 | G35: 46281 | H35: 46282 | I35: 3 Exit/Soak Checklists | K35: Critical | L35: Chưa bắt đầu
A36: WBS-3.9 | B36: Thiết kế quy trình | C36: W4 | D36: Tạo GO/NO-GO Decision Checklist | E36: Quy tắc không còn BLOCK/UNKNOWN critical, evidence hợp lệ, approver và hành động tiếp theo. | F36: 3.8 | G36: 46282 | H36: 46282 | I36: GO-NO-GO Checklist | K36: Critical | L36: Chưa bắt đầu
A37: WBS-3.10 | B37: Thiết kế quy trình | C37: W4 | D37: Xây Backup & Recovery Plan | E37: Phạm vi control-plane và data, RPO/RTO, off-cluster copy, retention, owner, restore validation. | F37: 1.9–1.11 | G37: 46279 | H37: 46281 | I37: Backup & Recovery Plan v0.1 | K37: Critical | L37: Chưa bắt đầu
A38: WBS-3.11 | B38: Thiết kế quy trình | C38: W4 | D38: Tạo Backup/Restore Runbook & Checklist | E38: Cách tạo evidence, checksum, restore mẫu; checklist được thực thi trước từng hop. | F38: 3.10 | G38: 46281 | H38: 46282 | I38: Backup artifacts v0.1 | K38: Critical | L38: Chưa bắt đầu
A39: WBS-3.12 | B39: Thiết kế quy trình | C39: W4 | D39: Xây Rollback/Fix-forward Plan | E39: Phân biệt rollback cấu hình/dịch vụ với downgrade; trigger, pause, fix-forward và recovery path. | F39: 3.2,3.10 | G39: 46281 | H39: 46283 | I39: Rollback/Fix-forward Plan v0.1 | K39: Critical | L39: Chưa bắt đầu
... A41: WBS-3.14 | B41: Thiết kế quy trình | C41: W4 | D41: Xây Lab Test Plan | E41: Functional, regression, performance, integrity, backup/restore, fault/failure và soak. | F41: 1.2,2.10 | G41: 46280 | H41: 46283 | I41: Lab Test Plan v0.1 | K41: Critical | L41: Chưa bắt đầu
A42: WBS-3.15 | B42: Thiết kế quy trình | C42: W4 | D42: Thiết kế Lab–Production Equivalence Matrix và IO workload ảo | E42: Mapping topology/daemon/service/client/OS/kernel/network/capacity/workload; ghi gap, impact và control. | F42: 1.5–1.11 | G42: 46279 | H42: 46283 | I42: Lab design + equivalence matrix + workload plan | J42: G2 | K42: Critical | L42: Chưa bắt đầu
A43: WBS-4.1 | B43: Dựng Lab & Baseline | C43: W5 | D43: Cấp phát tài nguyên Lab | E43: VM/bare metal, disk, network, registry, access, time sync và monitoring endpoints. | F43: 3.15 | G43: 46286 | H43: 46286 | I43: Lab resources ready | K43: Critical | L43: Chưa bắt đầu
...

Sheet 02_Gantt
A1: GANTT 10 TUẦN – CEPH UPGRADE PROJECT
A3: Timeline lấy từ Start/End trong 01_KeHoach; 50 ngày làm việc; hoàn tất trước 2026-11-01
A4: WBS | B4: Tuần | C4: Giai đoạn | D4: Công việc | E4: Bắt đầu | F4: Kết thúc | G4: TUẦN 1 | L4: TUẦN 2 | Q4: TUẦN 3 | V4: TUẦN 4 | AA4: TUẦN 5 | AF4: TUẦN 6 | AK4: TUẦN 7 | AP4: TUẦN 8 | AU4: TUẦN 9 | AZ4: TUẦN 10
G5: 46258 | H5: 46259 | I5: 46260 | J5: 46261 | K5: 46262 | L5: 46265 | M5: 46266 | N5: 46267 | O5: 46268 | P5: 46269 | Q5: 46272 | R5: 46273 | S5: 46274 | T5: 46275 | U5: 46276 | V5: 46279 | W5: 46280 | X5: 46281 | Y5: 46282 | Z5: 46283 | AA5: 46286 | AB5: 46287 | AC5: 46288 | AD5: 46289 | AE5: 46290 | AF5: 46293 | AG5: 46294 | AH5: 46295 | AI5: 46296 | AJ5: 46297 | AK5: 46300 | AL5: 46301 | AM5: 46302 | AN5: 46303 | AO5: 46304 | AP5: 46307 | AQ5: 46308 | AR5: 46309 | AS5: 46310 | AT5: 46311 | AU5: 46314 | AV5: 46315 | AW5: 46316 | AX5: 46317 | AY5: 46318 | AZ5: 46321 | BA5: 46322 | BB5: 46323 | BC5: 46324 | BD5: 46325
A6: ='01_KeHoach'!A6 -> WBS-1.1 | B6: ='01_KeHoach'!C6 -> W1 | C6: ='01_KeHoach'!B6 -> Khởi động & As-Is | D6: ='01_KeHoach'!D6 -> Kick-off, chốt phạm vi và mục tiêu | E6: ='01_KeHoach'!G6 -> 46258 | F6: ='01_KeHoach'!H6 -> 46258 | G6: =IF(AND(G$5>=$E6,G$5<=$F6),"■","") -> ■ | H6: =IF(AND(H$5>=$E6,H$5<=$F6),"■","") | I6: =IF(AND(I$5>=$E6,I$5<=$F6),"■","") | J6: =IF(AND(J$5>=$E6,J$5<=$F6),"■","") | K6: =IF(AND(K$5>=$E6,K$5<=$F6),"■","") | L6: =IF(AND(L$5>=$E6,L$5<=$F6),"■","") | M6: =IF(AND(M$5>=$E6,M$5<=$F6),"■","") | N6: =IF(AND(N$5>=$E6,N$5<=$F6),"■","") | ... BD6: =IF(AND(BD$5>=$E6,BD$5<=$F6),"■","")
A7: ='01_KeHoach'!A7 -> WBS-1.2 | B7: ='01_KeHoach'!C7 -> W1 | C7: ='01_KeHoach'!B7 -> Khởi động & As-Is | D7: ='01_KeHoach'!D7 -> Chốt tiêu chí nghiệm thu và SLA cần đo | E7: ='01_KeHoach'!G7 -> 46258 | F7: ='01_KeHoach'!H7 -> 46259 | G7: =IF(AND(G$5>=$E7,G$5<=$F7),"■","") -> ■ | H7: =IF(AND(H$5>=$E7,H$5<=$F7),"■","") -> ■ | I7: =IF(AND(I$5>=$E7,I$5<=$F7),"■","") | J7: =IF(AND(J$5>=$E7,J$5<=$F7),"■","") | K7: =IF(AND(K$5>=$E7,K$5<=$F7),"■","") | L7: =IF(AND(L$5>=$E7,L$5<=$F7),"■","") | M7: =IF(AND(M$5>=$E7,M$5<=$F7),"■","") | N7: =IF(AND(N$5>=$E7,N$5<=$F7),"■","") | ... BD7: =IF(AND(BD$5>=$E7,BD$5<=$F7),"■","")
A8: ='01_KeHoach'!A8 -> WBS-1.3 | B8: ='01_KeHoach'!C8 -> W1 | C8: ='01_KeHoach'!B8 -> Khởi động & As-Is | D8: ='01_KeHoach'!D8 -> Thiết lập evidence repository, index và yêu cầu Evidence Collector | E8: ='01_KeHoach'!G8 -> 46258 | F8: ='01_KeHoach'!H8 -> 46259 | G8: =IF(AND(G$5>=$E8,G$5<=$F8),"■","") -> ■ | H8: =IF(AND(H$5>=$E8,H$5<=$F8),"■","") -> ■ | I8: =IF(AND(I$5>=$E8,I$5<=$F8),"■","") | J8: =IF(AND(J$5>=$E8,J$5<=$F8),"■","") | K8: =IF(AND(K$5>=$E8,K$5<=$F8),"■","") | L8: =IF(AND(L$5>=$E8,L$5<=$F8),"■","") | M8: =IF(AND(M$5>=$E8,M$5<=$F8),"■","") | N8: =IF(AND(N$5>=$E8,N$5<=$F8),"■","") | ... BD8: =IF(AND(BD$5>=$E8,BD$5<=$F8),"■","")
A9: ='01_KeHoach'!A9 -> WBS-1.4 | B9: ='01_KeHoach'!C9 -> W1 | C9: ='01_KeHoach'!B9 -> Khởi động & As-Is | D9: ='01_KeHoach'!D9 -> Tạo As-Is Survey Checklist v0.1 | E9: ='01_KeHoach'!G9 -> 46258 | F9: ='01_KeHoach'!H9 -> 46259 | G9: =IF(AND(G$5>=$E9,G$5<=$F9),"■","") -> ■ | H9: =IF(AND(H$5>=$E9,H$5<=$F9),"■","") -> ■ | I9: =IF(AND(I$5>=$E9,I$5<=$F9),"■","") | J9: =IF(AND(J$5>=$E9,J$5<=$F9),"■","") | K9: =IF(AND(K$5>=$E9,K$5<=$F9),"■","") | L9: =IF(AND(L$5>=$E9,L$5<=$F9),"■","") | M9: =IF(AND(M$5>=$E9,M$5<=$F9),"■","") | N9: =IF(AND(N$5>=$E9,N$5<=$F9),"■","") | ... BD9: =IF(AND(BD$5>=$E9,BD$5<=$F9),"■","")
A10: ='01_KeHoach'!A10 -> WBS-1.5 | B10: ='01_KeHoach'!C10 -> W1 | C10: ='01_KeHoach'!B10 -> Khởi động & As-Is | D10: ='01_KeHoach'!D10 -> Khảo sát deployment và topology | E10: ='01_KeHoach'!G10 -> 46259 | F10: ='01_KeHoach'!H10 -> 46259 | G10: =IF(AND(G$5>=$E10,G$5<=$F10),"■","") | H10: =IF(AND(H$5>=$E10,H$5<=$F10),"■","") -> ■ | I10: =IF(AND(I$5>=$E10,I$5<=$F10),"■","") | J10: =IF(AND(J$5>=$E10,J$5<=$F10),"■","") | K10: =IF(AND(K$5>=$E10,K$5<=$F10),"■","") | L10: =IF(AND(L$5>=$E10,L$5<=$F10),"■","") | M10: =IF(AND(M$5>=$E10,M$5<=$F10),"■","") | N10: =IF(AND(N$5>=$E10,N$5<=$F10),"■","") | ... BD10: =IF(AND(BD$5>=$E10,BD$5<=$F10),"■","")
A11: ='01_KeHoach'!A11 -> WBS-1.6 | B11: ='01_KeHoach'!C11 -> W1 | C11: ='01_KeHoach'!B11 -> Khởi động & As-Is | D11: ='01_KeHoach'!D11 -> Khảo sát version distribution | E11: ='01_KeHoach'!G11 -> 46259 | F11: ='01_KeHoach'!H11 -> 46259 | G11: =IF(AND(G$5>=$E11,G$5<=$F11),"■","") | H11: =IF(AND(H$5>=$E11,H$5<=$F11),"■","") -> ■ | I11: =IF(AND(I$5>=$E11,I$5<=$F11),"■","") | J11: =IF(AND(J$5>=$E11,J$5<=$F11),"■","") | K11: =IF(AND(K$5>=$E11,K$5<=$F11),"■","") | L11: =IF(AND(L$5>=$E11,L$5<=$F11),"■","") | M11: =IF(AND(M$5>=$E11,M$5<=$F11),"■","") | N11: =IF(AND(N$5>=$E11,N$5<=$F11),"■","") | ... BD11: =IF(AND(BD$5>=$E11,BD$5<=$F11),"■","")
A12: ='01_KeHoach'!A12 -> WBS-1.7 | B12: ='01_KeHoach'!C12 -> W1 | C12: ='01_KeHoach'!B12 -> Khởi động & As-Is | D12: ='01_KeHoach'!D12 -> Khảo sát BlueStore/RocksDB và DB/WAL | E12: ='01_KeHoach'!G12 -> 46259 | F12: ='01_KeHoach'!H12 -> 46260 | G12: =IF(AND(G$5>=$E12,G$5<=$F12),"■","") | H12: =IF(AND(H$5>=$E12,H$5<=$F12),"■","") -> ■ | I12: =IF(AND(I$5>=$E12,I$5<=$F12),"■","") -> ■ | J12: =IF(AND(J$5>=$E12,J$5<=$F12),"■","") | K12: =IF(AND(K$5>=$E12,K$5<=$F12),"■","") | L12: =IF(AND(L$5>=$E12,L$5<=$F12),"■","") | M12: =IF(AND(M$5>=$E12,M$5<=$F12),"■","") | N12: =IF(AND(N$5>=$E12,N$5<=$F12),"■","") | ... BD12: =IF(AND(BD$5>=$E12,BD$5<=$F12),"■","")
A13: ='01_KeHoach'!A13 -> WBS-1.8 | B13: ='01_KeHoach'!C13 -> W1 | C13: ='01_KeHoach'!B13 -> Khởi động & As-Is | D13: ='01_KeHoach'!D13 -> Khảo sát pool, PG, CRUSH, capacity và health history | E13: ='01_KeHoach'!G13 -> 46260 | F13: ='01_KeHoach'!H13 -> 46260 | G13: =IF(AND(G$5>=$E13,G$5<=$F13),"■","") | H13: =IF(AND(H$5>=$E13,H$5<=$F13),"■","") | I13: =IF(AND(I$5>=$E13,I$5<=$F13),"■","") -> ■ | J13: =IF(AND(J$5>=$E13,J$5<=$F13),"■","") | K13: =IF(AND(K$5>=$E13,K$5<=$F13),"■","") | L13: =IF(AND(L$5>=$E13,L$5<=$F13),"■","") | M13: =IF(AND(M$5>=$E13,M$5<=$F13),"■","") | N13: =IF(AND(N$5>=$E13,N$5<=$F13),"■","") | ... BD13: =IF(AND(BD$5>=$E13,BD$5<=$F13),"■","")
A14: ='01_KeHoach'!A14 -> WBS-1.9 | B14: ='01_KeHoach'!C14 -> W1 | C14: ='01_KeHoach'!B14 -> Khởi động & As-Is | D14: ='01_KeHoach'!D14 -> Khảo sát dịch vụ và client | E14: ='01_KeHoach'!G14 -> 46260 | F14: ='01_KeHoach'!H14 -> 46261 | G14: =IF(AND(G$5>=$E14,G$5<=$F14),"■","") | H14: =IF(AND(H$5>=$E14,H$5<=$F14),"■","") | I14: =IF(AND(I$5>=$E14,I$5<=$F14),"■","") -> ■ | J14: =IF(AND(J$5>=$E14,J$5<=$F14),"■","") -> ■ | K14: =IF(AND(K$5>=$E14,K$5<=$F14),"■","") | L14: =IF(AND(L$5>=$E14,L$5<=$F14),"■","") | M14: =IF(AND(M$5>=$E14,M$5<=$F14),"■","") | N14: =IF(AND(N$5>=$E14,N$5<=$F14),"■","") | ... BD14: =IF(AND(BD$5>=$E14,BD$5<=$F14),"■","")
A15: ='01_KeHoach'!A15 -> WBS-1.10 | B15: ='01_KeHoach'!C15 -> W1 | C15: ='01_KeHoach'!B15 -> Khởi động & As-Is | D15: ='01_KeHoach'!D15 -> Khảo sát host platform và delivery artifact | E15: ='01_KeHoach'!G15 -> 46261 | F15: ='01_KeHoach'!H15 -> 46261 | G15: =IF(AND(G$5>=$E15,G$5<=$F15),"■","") | H15: =IF(AND(H$5>=$E15,H$5<=$F15),"■","") | I15: =IF(AND(I$5>=$E15,I$5<=$F15),"■","") | J15: =IF(AND(J$5>=$E15,J$5<=$F15),"■","") -> ■ | K15: =IF(AND(K$5>=$E15,K$5<=$F15),"■","") | L15: =IF(AND(L$5>=$E15,L$5<=$F15),"■","") | M15: =IF(AND(M$5>=$E15,M$5<=$F15),"■","") | N15: =IF(AND(N$5>=$E15,N$5<=$F15),"■","") | ... BD15: =IF(AND(BD$5>=$E15,BD$5<=$F15),"■","")
A16: ='01_KeHoach'!A16 -> WBS-1.11 | B16: ='01_KeHoach'!C16 -> W1 | C16: ='01_KeHoach'!B16 -> Khởi động & As-Is | D16: ='01_KeHoach'!D16 -> Khảo sát workload Production | E16: ='01_KeHoach'!G16 -> 46261 | F16: ='01_KeHoach'!H16 -> 46261 | G16: =IF(AND(G$5>=$E16,G$5<=$F16),"■","") | H16: =IF(AND(H$5>=$E16,H$5<=$F16),"■","") | I16: =IF(AND(I$5>=$E16,I$5<=$F16),"■","") | J16: =IF(AND(J$5>=$E16,J$5<=$F16),"■","") -> ■ | K16: =IF(AND(K$5>=$E16,K$5<=$F16),"■","") | L16: =IF(AND(L$5>=$E16,L$5<=$F16),"■","") | M16: =IF(AND(M$5>=$E16,M$5<=$F16),"■","") | N16: =IF(AND(N$5>=$E16,N$5<=$F16),"■","") | ... BD16: =IF(AND(BD$5>=$E16,BD$5<=$F16),"■","")
A17: ='01_KeHoach'!A17 -> WBS-1.12 | B17: ='01_KeHoach'!C17 -> W1 | C17: ='01_KeHoach'!B17 -> Khởi động & As-Is | D17: ='01_KeHoach'!D17 -> Phát hành As-Is Report và Blocker Register | E17: ='01_KeHoach'!G17 -> 46262 | F17: ='01_KeHoach'!H17 -> 46262 | G17: =IF(AND(G$5>=$E17,G$5<=$F17),"■","") | H17: =IF(AND(H$5>=$E17,H$5<=$F17),"■","") | I17: =IF(AND(I$5>=$E17,I$5<=$F17),"■","") | J17: =IF(AND(J$5>=$E17,J$5<=$F17),"■","") | K17: =IF(AND(K$5>=$E17,K$5<=$F17),"■","") -> ■ | L17: =IF(AND(L$5>=$E17,L$5<=$F17),"■","") | M17: =IF(AND(M$5>=$E17,M$5<=$F17),"■","") | N17: =IF(AND(N$5>=$E17,N$5<=$F17),"■","") | ... BD17: =IF(AND(BD$5>=$E17,BD$5<=$F17),"■","")
... A87: ='01_KeHoach'!A87 -> WBS-7.9 | B87: ='01_KeHoach'!C87 -> W10 | C87: ='01_KeHoach'!B87 -> Tổng hợp & Bàn giao | D87: ='01_KeHoach'!D87 -> Đóng gói và bàn giao | E87: ='01_KeHoach'!G87 -> 46325 | F87: ='01_KeHoach'!H87 -> 46325 | G87: =IF(AND(G$5>=$E87,G$5<=$F87),"■","") | H87: =IF(AND(H$5>=$E87,H$5<=$F87),"■","") | I87: =IF(AND(I$5>=$E87,I$5<=$F87),"■","") | J87: =IF(AND(J$5>=$E87,J$5<=$F87),"■","") | K87: =IF(AND(K$5>=$E87,K$5<=$F87),"■","") | L87: =IF(AND(L$5>=$E87,L$5<=$F87),"■","") | M87: =IF(AND(M$5>=$E87,M$5<=$F87),"■","") | N87: =IF(AND(N$5>=$E87,N$5<=$F87),"■","") | ... BD87: =IF(AND(BD$5>=$E87,BD$5<=$F87),"■","") -> ■

Sheet 03_DanhMucTaiLieu
A1: DANH MỤC TÀI LIỆU ĐẦU RA
A3: Mỗi tài liệu có bản nháp trước Lab, được cập nhật sau từng hop và phát hành bản cuối ở Tuần 10
A5: ID | B5: Nhóm | C5: Tài liệu | D5: Mục đích | E5: Áp dụng | F5: Tạo bản nháp | G5: Xác minh/Cập nhật | H5: Bản cuối | I5: Tiêu chí hoàn thành | J5: Trạng thái
A6: D01 | B6: Assessment | C6: As-Is Survey Checklist | D6: Thu thập fact có evidence và phát hiện UNKNOWN/BLOCK | E6: Toàn cluster | F6: W1 | G6: W1 | H6: W1 | I6: Checklist đã điền + evidence index | J6: Chưa bắt đầu
A7: D02 | B7: Assessment | C7: As-Is Report & Blocker Register | D7: Mô tả hiện trạng và blocker quyết định target/hop | E7: Toàn cluster | F7: W1 | G7: W1 | H7: W1 | I7: Gate G0 | J7: Chưa bắt đầu
A8: D03 | B8: Decision | C8: Target & Hop Decision Record | D8: Chốt target cuối và transit versions | E8: Toàn dự án | F8: W2 | G8: W3 | H8: W3 | I8: Gate G1 | J8: Chưa bắt đầu
A9: D04 | B9: Compatibility | C9: Compatibility Matrix H1 | D9: Pacific 16.2.5 → 16.2.15 | E9: H1 | F9: W2 | G9: W3/W7 | H9: W10 | I9: PASS/BLOCK theo từng domain | J9: Chưa bắt đầu
A10: D05 | B10: Compatibility | C10: Compatibility Matrix H2 | D10: Pacific 16.2.15 → Quincy 17.2.x | E10: H2 | F10: W2 | G10: W3/W8 | H10: W10 | I10: PASS/BLOCK theo từng domain | J10: Chưa bắt đầu
A11: D06 | B11: Compatibility | C11: Compatibility Matrix H3 | D11: Quincy 17.2.x → Reef 18.2.7 | E11: H3 | F11: W2 | G11: W3/W9 | H11: W10 | I11: PASS/BLOCK theo từng domain | J11: Chưa bắt đầu
A12: D07 | B12: Governance | C12: Risk & Mitigation Register | D12: Theo dõi blocker, risk, owner và residual risk | E12: Toàn dự án | F12: W1 | G12: Hàng tuần | H12: W10 | I12: Không còn risk critical chưa xử lý | J12: Chưa bắt đầu
A13: D08 | B13: Procedure | C13: Master Upgrade Strategy | D13: Nguyên tắc minimal downtime, gate, vai trò và phạm vi | E13: Toàn dự án | F13: W3 | G13: W4/W9 | H13: W10 | I13: Production-ready strategy | J13: Chưa bắt đầu
A14: D09 | B14: Procedure | C14: Master Upgrade Runbook | D14: Câu lệnh/thao tác, expected output, xử lý lỗi từng hop | E14: H1/H2/H3 | F14: W4 | G14: Sau từng hop | H14: W10 | I14: Runbook v1.0 được peer review | J14: Chưa bắt đầu
A15: D10 | B15: Backup | C15: Backup & Recovery Plan | D15: Scope, RPO/RTO, off-cluster copy, retention, owner | E15: Toàn dự án | F15: W4 | G15: W6/W10 | H15: W10 | I15: Restore evidence | J15: Chưa bắt đầu
A16: D11 | B16: Backup | C16: Backup/Restore Runbook | D16: Cách backup/verify/restore theo deployment và service | E16: Mỗi hop | F16: W4 | G16: W6/W10 | H16: W10 | I16: Dry-run pass | J16: Chưa bắt đầu
... A23: D18 | B23: Handover | C23: Final Project Package | D23: Bộ báo cáo, matrix, plans, runbook, checklist và Lab evidence | E23: Toàn dự án | F23: W10 | G23: W10 | H23: W10 | I23: Gate G11 | J23: Chưa bắt đầu

Sheet 04_DanhMucChecklist
A1: DANH MỤC CHECKLIST CẦN TẠO
A3: Checklist chung được thiết kế ở W4; checklist H1/H2/H3 được xác minh và chốt sau đúng hop tương ứng
A5: ID | B5: Nhóm | C5: Checklist | D5: Phạm vi | E5: Thời điểm dùng | F5: Mục đích/Nội dung chính | G5: Draft | H5: Finalize | I5: Gate liên quan | J5: Trạng thái
A6: CL01 | B6: Khảo sát | C6: As-Is Survey Checklist | D6: Toàn cluster | E6: Trước target selection | F6: Thu thập hiện trạng có evidence | G6: W1 | H6: W1 | I6: G0 | J6: Chưa bắt đầu
A7: CL02 | B7: Sẵn sàng | C7: Pre-upgrade Readiness Checklist chung | D7: Mọi hop | E7: T-7d/T-24h/T-30m | F7: Health, capacity, backend, client, artifact, access, equivalence gap, monitoring/automation | G7: W4 | H7: W10 | I7: G3/G4/G6/G8 | J7: Chưa bắt đầu
A8: CL03 | B8: Sẵn sàng | C8: Pre-hop Checklist H1 | D8: H1 | E8: Trước H1 | F8: Điều kiện riêng 16.2.5→16.2.15 | G8: W4 | H8: Sau H1 | I8: G4 | J8: Chưa bắt đầu
A9: CL04 | B9: Sẵn sàng | C9: Pre-hop Checklist H2 | D9: H2 | E9: Trước H2 | F9: Điều kiện riêng Pacific→Quincy | G9: W4 | H9: Sau H2 | I9: G6 | J9: Chưa bắt đầu
A10: CL05 | B10: Sẵn sàng | C10: Pre-hop Checklist H3 | D10: H3 | E10: Trước H3 | F10: Điều kiện riêng Quincy→Reef | G10: W4 | H10: Sau H3 | I10: G8 | J10: Chưa bắt đầu
A11: CL06 | B11: Giám sát | C11: Rolling Monitoring Checklist chung | D11: Mọi hop | E11: Trong upgrade | F11: Health/quorum/OSD/PG/version/crash/I/O/KPI + Evidence Collector/IO Sentinel và CONTINUE/PAUSE/STOP | G11: W4 | H11: W10 | I11: Mỗi batch | J11: Chưa bắt đầu
A12: CL07 | B12: Giám sát | C12: Rolling Monitoring Checklist H1 | D12: H1 | E12: Trong H1 | F12: Mixed-version và risk đặc thù H1 | G12: W4 | H12: Sau H1 | I12: G5 | J12: Chưa bắt đầu
A13: CL08 | B13: Giám sát | C13: Rolling Monitoring Checklist H2 | D13: H2 | E13: Trong H2 | F13: Mixed-version, backend/client/config đặc thù H2 | G13: W4 | H13: Sau H2 | I13: G7 | J13: Chưa bắt đầu
A14: CL09 | B14: Giám sát | C14: Rolling Monitoring Checklist H3 | D14: H3 | E14: Trong H3 | F14: Service/client/OSD risk đặc thù H3 | G14: W4 | H14: Sau H3 | I14: G9 | J14: Chưa bắt đầu
A15: CL10 | B15: Post-check | C15: Functional & Regression Checklist | D15: Mỗi hop | E15: Ngay sau hop | F15: RGW/RBD/CephFS và tính năng Production sử dụng | G15: W4 | H15: Sau từng hop | I15: Exit Gate | J15: Chưa bắt đầu
A16: CL11 | B16: Post-check | C16: Data Integrity Checklist | D16: Mỗi hop | E16: Trước/sau hop | F16: Checksum/object count/volume/file consistency | G16: W4 | H16: Sau từng hop | I16: Exit Gate | J16: Chưa bắt đầu
... A26: CL21 | B26: Bàn giao | C26: Final Acceptance Checklist | D26: Toàn dự án | E26: W10 | F26: Đủ deliverable, Traceability Matrix, evidence coverage, peer review và residual risks | G26: W10 | H26: W10 | I26: G11 | J26: Chưa bắt đầu

Sheet 05_LabTest
A1: LAB TEST MATRIX – TỪNG HOP, SOAK, FAULT VÀ FAILURE
A3: Threshold sự cố chốt sau W1 As-Is và W6 baseline; không dùng giá trị giả định làm tiêu chí Production
A5: Test ID | B5: Hop/Giai đoạn | C5: Loại | D5: Kịch bản | E5: Workload | F5: Điều kiện trước | G5: Tiêu chí PASS | H5: Gate | I5: Thời lượng | J5: Evidence | K5: Trạng thái
A6: EQ-01 | B6: Lab readiness | C6: Equivalence | D6: Xác minh Lab–Production Equivalence Matrix | E6: N/A | F6: As-Is inventory và Lab mapping đã hoàn tất | G6: 100% mapping critical; mọi gap có impact, control và owner | H6: G3 | I6: 2h | K6: Chưa bắt đầu
A7: LAB-02 | B7: Lab readiness | C7: Data integrity | D7: Seed dữ liệu và checksum manifest | E7: RGW/RBD/CephFS | F7: Dataset tái lập được trước mọi hop | G7: 100% manifest được tạo và lưu ngoài cluster Lab | H7: G3 | I7: 2h | K7: Chưa bắt đầu
A8: IO-01 | B8: Baseline | C8: Performance | D8: RGW mixed S3 workload | E8: PUT/GET/LIST/DELETE | F8: Profile theo Production; nếu thiếu dùng giả định có nhãn | G8: KPI baseline + 0 data loss | H8: G3 | I8: 60–120m | K8: Chưa bắt đầu
A9: IO-02 | B9: Baseline | C9: Functional | D9: RGW advanced functions | E9: IAM/Lifecycle/Versioning/Object Lock | F9: Chỉ chạy tính năng đang dùng | G9: Tất cả functional probes PASS | H9: G3 | I9: 60m | K9: Chưa bắt đầu
A10: IO-03 | B10: Baseline | C10: Performance | D10: RBD random workload | E10: fio-like randrw | F10: Block size/read-write ratio theo As-Is | G10: KPI baseline + checksum PASS | H10: G3 | I10: 60–120m | K10: Chưa bắt đầu
A11: IO-04 | B11: Baseline | C11: Performance | D11: RBD sequential workload | E11: Sequential read/write | F11: Đo throughput và latency | G11: KPI baseline + checksum PASS | H11: G3 | I11: 60m | K11: Chưa bắt đầu
A12: IO-05 | B12: Baseline | C12: Performance | D12: CephFS data/metadata workload | E12: Read/write/create/stat/delete | F12: Chỉ áp dụng nếu Production dùng CephFS | G12: KPI baseline + namespace integrity PASS | H12: G3 | I12: 60–120m | K12: Chưa bắt đầu
A13: H1-01 | B13: H1 | C13: Upgrade | D13: Rolling upgrade dưới steady IO | E13: Mixed service workload | F13: Pre-H1 GO + backup checkpoint | G13: Upgrade hoàn thành; I/O trong threshold | H13: G5 | I13: Theo runbook | K13: Chưa bắt đầu
A14: H1-02 | B14: H1 | C14: Monitoring | D14: Evidence Collector/IO Sentinel theo batch | E14: Continuous probes + dashboard | F14: Collector/Sentinel smoke test PASS | G14: Không vượt STOP; evidence đủ timestamp và không có gap giám sát | H14: G5 | I14: Trong upgrade | K14: Chưa bắt đầu
A15: H1-03 | B15: H1 | C15: Regression | D15: Functional + integrity post H1 | E15: RGW/RBD/CephFS | F15: 100% daemon target H1 | G15: Functional/checksum PASS | H15: G5 | I15: 2–4h | K15: Chưa bắt đầu
A16: H1-04 | B16: H1 | C16: Soak | D16: Soak H1 | E16: Steady mixed IO | F16: Post-check PASS | G16: Health/KPI ổn định 12–24h | H16: G5 | I16: 12–24h | K16: Chưa bắt đầu
A17: H2-01 | B17: H2 | C17: Upgrade | D17: Rolling Pacific→Quincy dưới IO | E17: Mixed service workload | F17: H1 Exit PASS + Pre-H2 GO | G17: Upgrade hoàn thành; I/O trong threshold | H17: G7 | I17: Theo runbook | K17: Chưa bắt đầu
... A32: B-02 | B32: Lab | C32: Restore | D32: Restore mẫu dữ liệu/dịch vụ | E32: Sample RGW/RBD/CephFS | F32: Backup gần nhất có thể truy cập | G32: Restore + checksum/functional PASS | H32: G3/G10 | I32: 2–4h | K32: Chưa bắt đầu

Sheet 06_Workload_IO
A1: KẾ HOẠCH IO WORKLOAD ẢO
A3: Concurrency/rate/read-write ratio lấy từ As-Is; IO Sentinel phải chạy liên tục từ baseline đến hết rehearsal
A5: Profile | B5: Dịch vụ | C5: Mô tả | D5: Kích thước | E5: Operation | F5: Concurrency/Rate | G5: Thời gian chạy | H5: Metrics | I5: Quy tắc sử dụng | J5: Trạng thái
A6: WL-01 | B6: RGW | C6: Small-object metadata-heavy | D6: 4 KiB–1 MiB | E6: PUT/GET/LIST/DELETE | F6: Theo As-Is; TBD | G6: T-15m đến T+60m mỗi hop | H6: Ops/s, 4xx/5xx, p95/p99 latency, checksum | I6: Thay tỷ lệ giả định bằng profile Production ở W1 | J6: Chưa bắt đầu
A7: WL-02 | B7: RGW | C7: Mixed object workload | D7: 1–64 MiB | E7: PUT/GET/DELETE | F7: Theo As-Is; TBD | G7: Baseline + suốt upgrade + soak | H7: Throughput, error rate, latency, object count/checksum | I7: Áp dụng IAM/Lifecycle/Versioning/Object Lock nếu có | J7: Chưa bắt đầu
A8: WL-03 | B8: RBD | C8: Random block IO | D8: 4/16/64 KiB | E8: randrw | F8: Read/write ratio theo As-Is | G8: Baseline + suốt upgrade | H8: IOPS, bandwidth, await, p95/p99, IO errors | I8: Dùng volume test riêng; quiesce nếu test app-consistent snapshot | J8: Chưa bắt đầu
A9: WL-04 | B9: RBD | C9: Sequential block IO | D9: 1 MiB | E9: read/write | F9: Theo As-Is; TBD | G9: Baseline và post-hop | H9: Throughput, latency, IO errors, checksum | I9: Không chạy quá tải làm sai lệch recovery test | J9: Chưa bắt đầu
A10: WL-05 | B10: CephFS | C10: Data path | D10: 4 KiB–1 MiB | E10: read/write | F10: Theo As-Is; TBD | G10: Baseline + suốt upgrade | H10: IOPS, bandwidth, latency, errors | I10: N/A nếu Production không dùng CephFS | J10: Chưa bắt đầu
A11: WL-06 | B11: CephFS | C11: Metadata path | D11: Small files | E11: create/stat/rename/delete | F11: Theo As-Is; TBD | G11: Baseline + post-hop | H11: Ops/s, latency, namespace integrity | I11: Theo dõi MDS state và client reconnect | J11: Chưa bắt đầu
A12: WL-07 | B12: Mixed | C12: Continuous IO Sentinel / steady service workload | D12: Kết hợp WL-01…06 | E12: Continuous + heartbeat | F12: Giữ tải ổn định | G12: Baseline + toàn bộ hop + soak + rehearsal | H12: Availability, error-gap duration, p95/p99, host/OSD metrics, timestamp continuity | I12: Nguồn chính để đo minimal downtime và phát hiện khoảng gián đoạn | J12: Chưa bắt đầu
A13: WL-08 | B13: Mixed | C13: Recovery workload | D13: Kết hợp steady + fault | E13: Continuous | F13: Tải bằng steady state đã chốt | G13: Trong recovery/backfill | H13: Client impact, recovery ETA, PG state, latency | I13: Chỉ dùng trong Lab với fault injection đã phê duyệt | J13: Chưa bắt đầu

Sheet 07_GO_NOGO
A1: GATE VÀ QUY TẮC GO / NO-GO
A3: Quy tắc nền: 0 BLOCK, 0 UNKNOWN critical, evidence hợp lệ/đủ timestamp và đúng người phê duyệt; N/A phải có lý do
A5: Gate | B5: Thời điểm | C5: Quyết định | D5: Điều kiện bắt buộc | E5: Evidence | F5: Trạng thái | G5: Hành động nếu không đạt | H5: Ghi chú
A6: G0 | B6: Cuối W1 | C6: As-Is complete | D6: As-Is fields critical có evidence; blocker/UNKNOWN có owner; workload và service scope đã chốt | E6: As-Is report + evidence index | F6: Chưa đánh giá | G6: Không qua G0 thì chưa chọn target
A7: G1 | B7: Cuối W3 | C7: Target/Hops approved | D7: Đường được hỗ trợ; compatibility H1/H2/H3 hoàn tất; target đã revalidate; 0 UNKNOWN critical chưa có treatment | E7: Decision Record + matrices | F7: Chưa đánh giá | G7: Chỉ G1 mới khóa target cho Lab
A8: G2 | B8: Cuối W4 | C8: Design documents ready | D8: Runbook/checklist/backup/rollback/test plan v0.1 có owner và expected evidence | E8: Document register | F8: Chưa đánh giá | G8: Bắt buộc trước dry-run
A9: G3 | B9: Cuối W6 | C9: Lab ready | D9: Lab base/services/workload; Equivalence Matrix; Evidence Collector; IO Sentinel; backup/restore và dry-run PASS | E9: Lab readiness + equivalence sign-off | F9: Chưa đánh giá | G9: Cho phép bắt đầu H1
A10: G4 | B10: W7 trước H1 | C10: Pre-H1 GO | D10: Health/capacity/quorum/OSD/PG/artifact/backup/checklist H1 PASS | E10: Pre-H1 evidence | F10: Chưa đánh giá | G10: Nếu BLOCK: không chạy H1
A11: G5 | B11: W7 sau H1 | C11: Exit H1 | D11: 100% daemon target H1; functional/integrity/KPI/soak PASS; không crash/blocker | E11: H1 Exit Checklist | F11: Chưa đánh giá | G11: Cho phép H2
A12: G6 | B12: W8 trước H2 | C12: Pre-H2 GO | D12: H1 exit PASS; backup mới; compatibility H2 và client/backend readiness PASS | E12: Pre-H2 evidence | F12: Chưa đánh giá | G12: Nếu BLOCK: giữ cluster tại 16.2.15
A13: G7 | B13: W8 sau H2 | C13: Exit H2 | D13: 100% daemon Quincy; functional/integrity/KPI/24h soak PASS | E13: H2 Exit Checklist | F13: Chưa đánh giá | G13: Cho phép H3
A14: G8 | B14: W9 trước H3 | C14: Pre-H3 GO | D14: H2 exit PASS; backup mới; compatibility H3/service/client readiness PASS | E14: Pre-H3 evidence | F14: Chưa đánh giá | G14: Nếu BLOCK: giữ tại Quincy và remediation
A15: G9 | B15: Cuối W9 | C15: Exit H3 | D15: 100% daemon Reef; full regression/integrity/KPI/48–72h soak PASS | E15: H3 Exit Checklist | F15: Chưa đánh giá | G15: Cho phép fault suite/final assessment
A16: G10 | B16: Cuối W10 | C16: Lab final decision | D16: Fault/failure, restore, pause/resume, post-fault soak và end-to-end rehearsal PASS; residual risk có owner | E16: Lab Test/Rehearsal Report + traceability | F16: Chưa đánh giá | G16: PASS/CONDITIONAL/NO-GO
A17: G11 | B17: 30/10/2026 | C17: Final acceptance | D17: Đủ report, matrix, runbook v1.0, plans, checklist pack, traceability, evidence và peer review | E17: Final package index | F17: Chưa đánh giá | G17: Kết thúc đề tài

Sheet 08_RuiRo
A1: RISK & MITIGATION REGISTER
A3: Likelihood/Impact: 1–5 | Score = Likelihood × Impact | Rating được tính tự động
A5: Risk ID | B5: Rủi ro | C5: Likelihood | D5: Impact | E5: Score | F5: Rating | G5: Mitigation/Control | H5: Thời điểm | I5: Trạng thái | J5: Residual risk/Ghi chú
A6: R01 | B6: Deployment mode/mixed management chưa rõ | C6: 4 | D6: 5 | E6: =C6*D6 -> 20 | F6: =IF(E6>=15,"Critical",IF(E6>=10,"High",IF(E6>=5,"Medium","Low"))) -> Critical | G6: Khảo sát managed scope; BLOCK nếu daemon không có cơ chế nâng cụ thể | H6: W1 | I6: Open
A7: R02 | B7: OS/kernel/container/repository không hỗ trợ target | C7: 3 | D7: 5 | E7: =C7*D7 -> 15 | F7: =IF(E7>=15,"Critical",IF(E7>=10,"High",IF(E7>=5,"Medium","Low"))) -> Critical | G7: Host cohort matrix; test pull/install trên mọi cohort; chốt target theo compatibility | H7: W1–W2 | I7: Open
A8: R03 | B8: Còn FileStore/backend không phù hợp major hop | C8: 3 | D8: 5 | E8: =C8*D8 -> 15 | F8: =IF(E8>=15,"Critical",IF(E8>=10,"High",IF(E8>=5,"Medium","Low"))) -> Critical | G8: Xác minh 100% objectstore; remediation trước H2 | H8: W1–W2 | I8: Open
A9: R04 | B9: Client RGW/RBD/CephFS không tương thích | C9: 3 | D9: 5 | E9: =C9*D9 -> 15 | F9: =IF(E9>=15,"Critical",IF(E9>=10,"High",IF(E9>=5,"Medium","Low"))) -> Critical | G9: Client inventory + compatibility + regression suite trong mixed-version window | H9: W1–W9 | I9: Open
A10: R05 | B10: Dung lượng/recovery headroom không đủ | C10: 3 | D10: 5 | E10: =C10*D10 -> 15 | F10: =IF(E10>=15,"Critical",IF(E10>=10,"High",IF(E10>=5,"Medium","Low"))) -> Critical | G10: Capacity analysis, failure-domain simulation và gate trước mỗi hop | H10: W1–W9 | I10: Open
A11: R06 | B11: Backup tồn tại nhưng không restore được | C11: 3 | D11: 5 | E11: =C11*D11 -> 15 | F11: =IF(E11>=15,"Critical",IF(E11>=10,"High",IF(E11>=5,"Medium","Low"))) -> Critical | G11: Off-cluster copy, checksum và restore sample trong W6/W10 | H11: W4–W10 | I11: Open
A12: R07 | B12: Hiểu rollback là downgrade in-place | C12: 4 | D12: 5 | E12: =C12*D12 -> 20 | F12: =IF(E12>=15,"Critical",IF(E12>=10,"High",IF(E12>=5,"Medium","Low"))) -> Critical | G12: Rollback/Fix-forward Plan; stop/pause/recovery trigger; Lab validation | H12: W4–W10 | I12: Open
A13: R08 | B13: Lab không đại diện workload Production | C13: 4 | D13: 4 | E13: =C13*D13 -> 16 | F13: =IF(E13>=15,"Critical",IF(E13>=10,"High",IF(E13>=5,"Medium","Low"))) -> Critical | G13: Lab–Production Equivalence Matrix; ghi gap/impact/control; profile từ As-Is | H13: W1–W6 | I13: Open
A14: R09 | B14: Monitoring/collector thiếu hoặc lệch timestamp nên không đo được minimal downtime | C14: 3 | D14: 4 | E14: =C14*D14 -> 12 | F14: =IF(E14>=15,"Critical",IF(E14>=10,"High",IF(E14>=5,"Medium","Low"))) -> High | G14: Dashboard, NTP/clock check, collector smoke test và IO Sentinel heartbeat trước baseline | H14: W5–W9 | I14: Open
A15: R10 | B15: Target patch/lifecycle hoặc đường hỗ trợ thay đổi sau khi chốt | C15: 3 | D15: 4 | E15: =C15*D15 -> 12 | F15: =IF(E15>=15,"Critical",IF(E15>=10,"High",IF(E15>=5,"Medium","Low"))) -> High | G15: Revalidate nguồn chính thức tại G1, trước G3 và trước H1; cập nhật Decision Record | H15: W2–W7 | I15: Open
A16: R11 | B16: Fault test gây nhiễu final soak | C16: 3 | D16: 3 | E16: =C16*D16 -> 9 | F16: =IF(E16>=15,"Critical",IF(E16>=10,"High",IF(E16>=5,"Medium","Low"))) -> Medium | G16: Chỉ fault sau post-check; bắt đầu post-fault soak mới trước final gate | H16: W10 | I16: Open
A17: R12 | B17: Thay đổi config/default bị bật đồng thời với upgrade | C17: 3 | D17: 4 | E17: =C17*D17 -> 12 | F17: =IF(E17>=15,"Critical",IF(E17>=10,"High",IF(E17>=5,"Medium","Low"))) -> High | G17: Tách feature enablement khỏi version upgrade trừ khi bắt buộc; ghi decision record | H17: W7–W9 | I17: Open
